<?xml version="1.0"?>
<robot name="test_robot">

  <material name="blue">
    <color rgba="0 0 0.8 1"/>
  </material>

  <material name="green">
    <color rgba="0 1 0 1"/>
  </material>

  <material name="red">
    <color rgba="0.8 0 0 1"/>
  </material>
<!-- 
  <joint name="camera_joint" type="fixed">
    <parent link="camera_link"/>
    <child link="base_link"/>
    <origin xyz="0.5 0.5 0"/>
  </joint>

 -->  <link name="base_link">
    <visual>
     <geometry>
      <mesh filename="package://manipulator/meshes/base_bracket.stl" scale="0.01 0.01 0.01"/>
     </geometry>
     <material name="blue"/>
    </visual>
    <collision>
     <geometry>
      <mesh filename="package://manipulator/meshes/base_bracket.stl" scale="0.01 0.01 0.01"/>
     </geometry>
    </collision>
  </link>

  <joint name="joint1" type="fixed">
    <parent link="base_link"/>
    <child link="base_bracket_right"/>
    <origin xyz="0 0 0"/>
  </joint>

  <link name="base_bracket_right">
    <visual>
     <geometry>
      <mesh filename="package://manipulator/meshes/base_bracket.stl" scale="0.01 0.01 0.01"/>
     </geometry>
     <material name="blue"/>
     <origin rpy="0 0 3.1415" xyz="0 0 0"/>
    </visual>
    <collision>
     <geometry>
      <mesh filename="package://manipulator/meshes/base_bracket.stl" scale="0.01 0.01 0.01"/>
     </geometry>
    </collision>
  </link>

  <joint name="joint2" type="fixed">
    <parent link="base_link"/>
    <child link="base_servo_bracket"/>
    <origin rpy="0 0 1.5707" xyz="0.15 0.21 0"/>
  </joint>

  <link name="base_servo_bracket">
    <visual>
     <geometry>
      <mesh filename="package://manipulator/meshes/servo_bracket.stl" scale="0.01 0.01 0.01"/>
     </geometry>
     <material name="green"/>
     <origin rpy="0 0 1.5707" xyz="0 0 0"/>
    </visual>
    <collision>
     <geometry>
      <mesh filename="package://manipulator/meshes/servo_bracket.stl" scale="0.01 0.01 0.01"/>
     </geometry>
    </collision>
  </link>


  <joint name="joint3" type="fixed">
    <parent link="base_servo_bracket"/>
    <child link="base_servo"/>
    <origin xyz="-0.15 0 0.24"/>
  </joint>

  <link name="base_servo">
    <visual>
     <geometry>
      <mesh filename="package://manipulator/meshes/servo.stl" scale="0.01 0.01 0.01"/>
     </geometry>
     <material name="red"/>
     <origin rpy="1.5707 0 -1.5707" xyz="0 0 0"/>
    </visual>
    <collision>
     <geometry>
      <mesh filename="package://manipulator/meshes/servo.stl" scale="0.01 0.01 0.01"/>
     </geometry>
    </collision>
  </link>


  <joint name="joint4" type="revolute">
    <parent link="base_servo"/>
    <child link="base_servo_disc"/>
    <origin rpy="-1.5707 0 0" xyz="0 -0.105 0.27"/>
    <axis xyz="0 1 0"/>
    <limit effort="1000.0" lower="0.0" upper="3.1415" velocity="0.5"/>
  </joint>

  <link name="base_servo_disc">
    <visual>
     <geometry>
      <mesh filename="package://manipulator/meshes/servo_disc.stl" scale="0.01 0.01 0.01"/>
     </geometry>
     <material name="blue"/>
     <origin rpy="0 0 0" xyz="0 0 0"/>
    </visual>
    <collision>
     <geometry>
      <mesh filename="package://manipulator/meshes/servo_disc.stl" scale="0.01 0.01 0.01"/>
     </geometry>
    </collision>
  </link>


  <!-- Shoulder 1 block -->

  <joint name="joint5" type="fixed">
    <parent link="base_servo_disc"/>
    <child link="shoulder_servo_bracket"/>
    <origin rpy="3.1415 0 1.5707" xyz="-0.1 0 0.25"/>
  </joint>

  <link name="shoulder_servo_bracket">
    <visual>
     <geometry>
      <mesh filename="package://manipulator/meshes/servo_bracket.stl" scale="0.01 0.01 0.01"/>
     </geometry>
     <material name="green"/>
     <origin rpy="0 0 1.5707" xyz="0 0 0"/>
    </visual>
    <collision>
     <geometry>
      <mesh filename="package://manipulator/meshes/servo_bracket.stl" scale="0.01 0.01 0.01"/>
     </geometry>
    </collision>
  </link>


  <joint name="joint6" type="fixed">
    <parent link="shoulder_servo_bracket"/>
    <child link="shoulder_servo"/>
    <origin xyz="-0.15 0 0.24"/>
  </joint>

  <link name="shoulder_servo">
    <visual>
     <geometry>
      <mesh filename="package://manipulator/meshes/servo.stl" scale="0.01 0.01 0.01"/>
     </geometry>
     <material name="red"/>
     <origin rpy="1.5707 0 -1.5707" xyz="0 0 0"/>
    </visual>
    <collision>
     <geometry>
      <mesh filename="package://manipulator/meshes/servo.stl" scale="0.01 0.01 0.01"/>
     </geometry>
    </collision>
  </link>


  <joint name="joint7" type="revolute">
    <parent link="shoulder_servo"/>
    <child link="shoulder_servo_disc"/>
    <origin rpy="-1.5707 0 0" xyz="0 -0.105 0.27"/>
    <axis xyz="0 1 0"/>
    <limit effort="1000.0" lower="0.0" upper="3.1415" velocity="0.5"/>
  </joint>

  <link name="shoulder_servo_disc">
    <visual>
     <geometry>
      <mesh filename="package://manipulator/meshes/servo_disc.stl" scale="0.01 0.01 0.01"/>
     </geometry>
     <material name="blue"/>
     <origin rpy="0 0 0" xyz="0 0 0"/>
    </visual>
    <collision>
     <geometry>
      <mesh filename="package://manipulator/meshes/servo_disc.stl" scale="0.01 0.01 0.01"/>
     </geometry>
    </collision>
  </link>

  <joint name="joint8" type="fixed">
    <parent link="shoulder_servo_disc"/>
    <child link="shoulder_bracket"/>
    <origin rpy="1.5707 0 -1.5707" xyz="0 0.26 -0.5"/>
  </joint>

  <link name="shoulder_bracket">
    <visual>
     <geometry>
      <mesh filename="package://manipulator/meshes/u_bracket.stl" scale="0.01 0.01 0.01"/>
     </geometry>
     <material name="red"/>
    </visual>
    <collision>
     <geometry>
      <mesh filename="package://manipulator/meshes/u_bracket.stl" scale="0.01 0.01 0.01"/>
     </geometry>
    </collision>
  </link>


  <!-- Shoulder 2 block -->

  <joint name="joint9" type="fixed">
    <parent link="shoulder_bracket"/>
    <child link="shoulder2_bracket"/>
    <origin rpy="3.1415 0 0" xyz="0 0 0"/>
  </joint>

  <link name="shoulder2_bracket">
    <visual>
     <geometry>
      <mesh filename="package://manipulator/meshes/u_bracket.stl" scale="0.01 0.01 0.01"/>
     </geometry>
     <material name="red"/>
    </visual>
    <collision>
     <geometry>
      <mesh filename="package://manipulator/meshes/u_bracket.stl" scale="0.01 0.01 0.01"/>
     </geometry>
    </collision>
  </link>

  <joint name="joint10" type="revolute">
    <parent link="shoulder2_bracket"/>
    <child link="shoulder2_servo_disc"/>
    <origin rpy="0 0 1.5707" xyz="0.26 0.5 0"/>
    <axis xyz="0 1 0"/>
    <limit effort="1000.0" lower="-1.5707" upper="1.5707" velocity="0.5"/>
  </joint>

  <link name="shoulder2_servo_disc">
    <visual>
     <geometry>
      <mesh filename="package://manipulator/meshes/servo_disc.stl" scale="0.01 0.01 0.01"/>
     </geometry>
     <material name="blue"/>
     <origin rpy="0 0 0" xyz="0 0 0"/>
    </visual>
    <collision>
     <geometry>
      <mesh filename="package://manipulator/meshes/servo_disc.stl" scale="0.01 0.01 0.01"/>
     </geometry>
    </collision>
  </link>

  <joint name="joint11" type="fixed">
    <parent link="shoulder2_servo_disc"/>
    <child link="shoulder2_servo"/>
    <origin rpy="3.1415 3.1415 0" xyz="0.105 0.27 0"/>
  </joint>

  <link name="shoulder2_servo">
    <visual>
     <geometry>
      <mesh filename="package://manipulator/meshes/servo.stl" scale="0.01 0.01 0.01"/>
     </geometry>
     <material name="red"/>
     <origin rpy="0 0 0" xyz="0 0 0"/>
    </visual>
    <collision>
     <geometry>
      <mesh filename="package://manipulator/meshes/servo.stl" scale="0.01 0.01 0.01"/>
     </geometry>
    </collision>
  </link>

  <joint name="joint12" type="fixed">
    <parent link="shoulder2_servo"/>
    <child link="shoulder2_servo_bracket"/>
    <origin rpy="-1.5707 0 0" xyz="0 -0.24 0.15"/>
  </joint>

  <link name="shoulder2_servo_bracket">
    <visual>
     <geometry>
      <mesh filename="package://manipulator/meshes/servo_bracket.stl" scale="0.01 0.01 0.01"/>
     </geometry>
     <material name="green"/>
     <origin rpy="0 0 0" xyz="0 0 0"/>
    </visual>
    <collision>
     <geometry>
      <mesh filename="package://manipulator/meshes/servo_bracket.stl" scale="0.01 0.01 0.01"/>
     </geometry>
    </collision>
  </link>


  <!-- Elbow block -->

  <joint name="joint13" type="fixed">
    <parent link="shoulder2_servo_bracket"/>
    <child link="elbow_servo_bracket"/>
    <origin rpy="0 0 -1.5707" xyz="-1.0 0 0"/>
  </joint>

  <link name="elbow_servo_bracket">
    <visual>
     <geometry>
      <mesh filename="package://manipulator/meshes/servo_bracket.stl" scale="0.01 0.01 0.01"/>
     </geometry>
     <material name="green"/>
     <origin rpy="0 0 1.5707" xyz="0 0 0"/>
    </visual>
    <collision>
     <geometry>
      <mesh filename="package://manipulator/meshes/servo_bracket.stl" scale="0.01 0.01 0.01"/>
     </geometry>
    </collision>
  </link>

  <joint name="joint14" type="fixed">
    <parent link="elbow_servo_bracket"/>
    <child link="elbow_servo"/>
    <origin xyz="-0.15 0 0.24"/>
  </joint>

  <link name="elbow_servo">
    <visual>
     <geometry>
      <mesh filename="package://manipulator/meshes/servo.stl" scale="0.01 0.01 0.01"/>
     </geometry>
     <material name="red"/>
     <origin rpy="1.5707 0 -1.5707" xyz="0 0 0"/>
    </visual>
    <collision>
     <geometry>
      <mesh filename="package://manipulator/meshes/servo.stl" scale="0.01 0.01 0.01"/>
     </geometry>
    </collision>
  </link>


  <joint name="joint15" type="revolute">
    <parent link="elbow_servo"/>
    <child link="elbow_servo_disc"/>
    <origin rpy="-1.5707 0 0" xyz="0 -0.105 0.27"/>
    <axis xyz="0 1 0"/>
    <limit effort="1000.0" lower="0.0" upper="3.1415" velocity="0.5"/>
  </joint>

  <link name="elbow_servo_disc">
    <visual>
     <geometry>
      <mesh filename="package://manipulator/meshes/servo_disc.stl" scale="0.01 0.01 0.01"/>
     </geometry>
     <material name="blue"/>
     <origin rpy="0 0 0" xyz="0 0 0"/>
    </visual>
    <collision>
     <geometry>
      <mesh filename="package://manipulator/meshes/servo_disc.stl" scale="0.01 0.01 0.01"/>
     </geometry>
    </collision>
  </link>

  <joint name="joint16" type="fixed">
    <parent link="elbow_servo_disc"/>
    <child link="elbow_bracket"/>
    <origin rpy="1.5707 0 -1.5707" xyz="0 0.26 -0.5"/>
  </joint>

  <link name="elbow_bracket">
    <visual>
     <geometry>
      <mesh filename="package://manipulator/meshes/u_bracket.stl" scale="0.01 0.01 0.01"/>
     </geometry>
     <material name="red"/>
    </visual>
    <collision>
     <geometry>
      <mesh filename="package://manipulator/meshes/u_bracket.stl" scale="0.01 0.01 0.01"/>
     </geometry>
    </collision>
  </link>







  <!-- Shoulder 2 block -->
<!-- 
  <joint name="joint9" type="fixed">
    <parent link="shoulder_bracket_1"/>
    <child link="shoulder2_servo_bracket"/>
    <origin rpy="0 1.5707 3.1415" xyz="0.25 -0.61 -0.15"/>
  </joint>

  <link name="shoulder2_servo_bracket">
    <visual>
     <geometry>
      <mesh filename="package://manipulator/meshes/servo_bracket.stl" scale="0.01 0.01 0.01"/>
     </geometry>
     <material name="green"/>
     <origin rpy="0 0 1.5707" xyz="0 0 0"/>
    </visual>
    <collision>
     <geometry>
      <mesh filename="package://manipulator/meshes/servo_bracket.stl" scale="0.01 0.01 0.01"/>
     </geometry>
    </collision>
  </link>


  <joint name="joint10" type="fixed">
    <parent link="shoulder2_servo_bracket"/>
    <child link="shoulder2_servo"/>
    <origin xyz="-0.15 0 0.24"/>
  </joint>

  <link name="shoulder2_servo">
    <visual>
     <geometry>
      <mesh filename="package://manipulator/meshes/servo.stl" scale="0.01 0.01 0.01"/>
     </geometry>
     <material name="red"/>
     <origin rpy="1.5707 0 -1.5707" xyz="0 0 0"/>
    </visual>
    <collision>
     <geometry>
      <mesh filename="package://manipulator/meshes/servo.stl" scale="0.01 0.01 0.01"/>
     </geometry>
    </collision>
  </link>


  <joint name="joint11" type="revolute">
    <parent link="shoulder2_servo"/>
    <child link="shoulder2_servo_disc"/>
    <origin rpy="-1.5707 0 0" xyz="0 -0.105 0.27"/>
    <axis xyz="0 1 0"/>
    <limit effort="1000.0" lower="0.0" upper="3.1415" velocity="0.5"/>
  </joint>

  <link name="shoulder2_servo_disc">
    <visual>
     <geometry>
      <mesh filename="package://manipulator/meshes/servo_disc.stl" scale="0.01 0.01 0.01"/>
     </geometry>
     <material name="blue"/>
     <origin rpy="0 0 0" xyz="0 0 0"/>
    </visual>
    <collision>
     <geometry>
      <mesh filename="package://manipulator/meshes/servo_disc.stl" scale="0.01 0.01 0.01"/>
     </geometry>
    </collision>
  </link>


  <joint name="joint12" type="fixed">
    <parent link="shoulder2_servo_disc"/>
    <child link="shoulder2_bracket_1"/>
    <origin rpy="1.5707 0 -1.5707" xyz="0 0.26 -0.5"/>
  </joint>

  <link name="shoulder2_bracket_1">
    <visual>
     <geometry>
      <mesh filename="package://manipulator/meshes/u_bracket.stl" scale="0.01 0.01 0.01"/>
     </geometry>
     <material name="red"/>
    </visual>
    <collision>
     <geometry>
      <mesh filename="package://manipulator/meshes/u_bracket.stl" scale="0.01 0.01 0.01"/>
     </geometry>
    </collision>
  </link>

 -->








<!--
  <joint name="joint2" type="revolute">
    <axis xyz="-1 0 0" />
    <limit effort="1000.0" lower="-1.708" upper="1.708" velocity="1.0" />
    <origin xyz="0 0 0.093" rpy="0 0 0" />
    <parent link="platform"/>
    <child link="lower_arm"/>
  </joint>

  <joint name="joint3" type="revolute">
    <axis xyz="1 0 0" />
    <limit effort="1000.0" lower="-1.708" upper="1.708" velocity="1.0" />
    <origin xyz="0 0 0.121" rpy="0 0 0" />
    <parent link="lower_arm"/>
    <child link="upper_arm"/>
  </joint>

  <joint name="joint4" type="revolute">
    <axis xyz="-1 0 0" />
    <limit effort="1000.0" lower="-1.708" upper="1.708" velocity="1.0" />
    <origin xyz="0 0 0.112" rpy="0 0 0" />
    <parent link="upper_arm"/>
    <child link="wrist"/>
  </joint>

  <joint name="joint5" type="fixed">
    <axis xyz="-1 0 0" />
    <origin xyz="0 0 0.112" rpy="0 0 0" />
    <parent link="wrist"/>
    <child link="claw_base"/>
  </joint>

  <joint name="joint6" type="revolute">
    <axis xyz="0 1 0" />
    <limit effort="1000.0" lower="-0.15" upper="0.30" velocity="1.0" />
    <origin xyz="-0.027 0 0" rpy="0 0 0" />
    <parent link="claw_base"/>
    <child link="claw_l"/>
  </joint>

  <joint name="joint7" type="revolute">
    <axis xyz="0 -1 0" />
    <limit effort="1000.0" lower="-0.15" upper="0.30" velocity="1.0" />
    <origin xyz="-0.027 0 0" rpy="0 0 0" />
    <parent link="claw_base"/>
    <child link="claw_r"/>
  </joint> -->

</robot>
